<?xml version="1.0" ?>
<robot name="bmirobot" xmlns:xacro="http://www.ros.org/wiki/xacro">
 <!-- Constants for robot dimensions -->
  <xacro:property name="PI" value="3.1415926535897931"/>
  <xacro:property name="mass" value="1" /> <!-- arbitrary value for mass -->
  <xacro:property name="width" value="0.1" /> <!-- Square dimensions (widthxwidth) of beams -->
  <xacro:property name="height1" value="2" /> <!-- Link 1 -->
  <xacro:property name="height2" value="1" /> <!-- Link 2 -->
  <xacro:property name="height3" value="1" /> <!-- Link 3 -->
  <xacro:property name="camera_link" value="0.025" /> <!-- Size of square 'camera' box -->
  <xacro:property name="axel_offset" value="0.05" /> <!-- Space btw top of beam and the each joint -->

  <!-- Import all Gazebo-customization elements, including Gazebo colors -->
  <!--xacro:include filename="$(find bmirobot_description)/urdf/bmirobot.gazebo" /-->
  <!-- Import Rviz colors -->
  <xacro:include filename="$(find bmirobot_description)/urdf/materials.xacro" />
  
  <!-- Used for fixing robot to Gazebo 'base_link' -->
  <link name="world"/>

  <joint name="fixed" type="fixed">
    <parent link="world"/>
    <child link="odom_combined"/>
  </joint>

  <link name="odom_combined"/>

  <joint name="virtual_joint" type="fixed">
    <parent link="odom_combined"/>
    <child link="base_link"/>
    <origin xyz="0 0 0.45" rpy="0 0 0" />
  </joint>

  <link name="base_link">
    <visual>
      <geometry>
        <mesh filename="package://test_robot/stl/link1.STL"/>
      </geometry>
      <material name="blue"/>
    </visual>
    <collision>
      <geometry>
        <mesh filename="package://test_robot/stl/link1.STL"/>
      </geometry>
    </collision>
    <inertial>
      <origin xyz="0 0 1" rpy="0 0 0"/>
      <mass value="1"/>
      <inertia
        ixx="1.0" ixy="0.0" ixz="0.0"
        iyy="1.0" iyz="0.0"
        izz="1.0"/>
    </inertial>
  </link>

  <link name="link2" >
    <visual>
      <geometry>
        <mesh filename="package://test_robot/stl/link2.STL"/>
      </geometry>
      <origin xyz="0 0 0" rpy="0 0 0" />
      <material name="white"/>
    </visual>
    <collision>
      <geometry>
        <mesh filename="package://test_robot/stl/link2.STL"/>
      </geometry>
      <origin xyz="0 0 0" rpy="0 0 0" />
    </collision>
    <inertial>
      <origin xyz="0 0 1" rpy="0 0 0"/>
      <mass value="1"/>
      <inertia
        ixx="1.0" ixy="0.0" ixz="0.0"
        iyy="1.0" iyz="0.0"
        izz="1.0"/>
    </inertial>  
  </link>
  <link name="link3" >
    <visual>
      <geometry>
        <mesh filename="package://test_robot/stl/link3.STL"/>
      </geometry>
      <origin xyz="0 0 0" rpy="0 0 0" />
      <material name="blue"/>
    </visual>
    <collision>
      <geometry>
        <mesh filename="package://test_robot/stl/link3.STL"/>
      </geometry>
      <origin xyz="0 0 0" rpy="0 0 0" />
    </collision>
    <inertial>
      <origin xyz="0 0 1" rpy="0 0 0"/>
      <mass value="1"/>
      <inertia
        ixx="1.0" ixy="0.0" ixz="0.0"
        iyy="1.0" iyz="0.0"
        izz="1.0"/>
    </inertial>
  </link>
  <link name="link4" >
    <visual>
      <geometry>
        <mesh filename="package://test_robot/stl/link2.STL"/>
      </geometry>
      <origin xyz="0 0 0" rpy="0 0 0" />
      <material name="white"/>
    </visual>
    <collision>
      <geometry>
        <mesh filename="package://test_robot/stl/link2.STL"/>
      </geometry>
      <origin xyz="0 0 0" rpy="0 0 0" />
    </collision>
    <inertial>
      <origin xyz="0 0 1" rpy="0 0 0"/>
      <mass value="1"/>
      <inertia
        ixx="1.0" ixy="0.0" ixz="0.0"
        iyy="1.0" iyz="0.0"
        izz="1.0"/>
    </inertial>
  </link>
  <link name="link5" >
    <visual>
      <geometry>
        <mesh filename="package://test_robot/stl/link5.STL"/>
      </geometry>
      <origin xyz="0 0 0" rpy="0 0 0" />
      <material name="blue"/>
    </visual>
    <collision>
      <geometry>
        <mesh filename="package://test_robot/stl/link5.STL"/>
      </geometry>
      <origin xyz="0 0 0" rpy="0 0 0" />
    </collision>
    <inertial>
      <origin xyz="0 0 1" rpy="0 0 0"/>
      <mass value="1"/>
      <inertia
        ixx="1.0" ixy="0.0" ixz="0.0"
        iyy="1.0" iyz="0.0"
        izz="1.0"/>
    </inertial>
  </link>
  <link name="link6" >
    <visual>
      <geometry>
        <mesh filename="package://test_robot/stl/link6.STL"/>
      </geometry>
      <origin xyz="0 0 0" rpy="0 0 0" />
      <material name="white"/>
    </visual>
    <collision>
      <geometry>
        <mesh filename="package://test_robot/stl/link6.STL"/>
      </geometry>
      <origin xyz="0 0 0" rpy="0 0 0" />
    </collision>
    <inertial>
      <origin xyz="0 0 1" rpy="0 0 0"/>
      <mass value="1"/>
      <inertia
        ixx="1.0" ixy="0.0" ixz="0.0"
        iyy="1.0" iyz="0.0"
        izz="1.0"/>
    </inertial>
  </link>
  <link name="link7" >
    <visual>
      <geometry>
        <mesh filename="package://test_robot/stl/link7.STL"/>
      </geometry>
      <origin xyz="0 0 0" rpy="0 0 0" />
      <material name="blue"/>
    </visual>
    <collision>
      <geometry>
        <mesh filename="package://test_robot/stl/link7.STL"/>
      </geometry>
      <origin xyz="0 0 0" rpy="0 0 0" />
    </collision>
    <inertial>
      <origin xyz="0 0 1" rpy="0 0 0"/>
      <mass value="1"/>
      <inertia
        ixx="1.0" ixy="0.0" ixz="0.0"
        iyy="1.0" iyz="0.0"
        izz="1.0"/>
    </inertial>
  </link>
  <link name="link8" >
    <visual>
      <geometry>
        <mesh filename="package://test_robot/stl/link8.STL"/>
      </geometry>
      <origin xyz="0 0 0" rpy="0 0 0" />
      <material name="white"/>
    </visual>
    <collision>
      <geometry>
        <mesh filename="package://test_robot/stl/link8.STL"/>
      </geometry>
      <origin xyz="0 0 0" rpy="0 0 0" />
    </collision>
    <inertial>
      <origin xyz="0 0 1" rpy="0 0 0"/>
      <mass value="1"/>
      <inertia
        ixx="1.0" ixy="0.0" ixz="0.0"
        iyy="1.0" iyz="0.0"
        izz="1.0"/>
    </inertial>
  </link>
  <link name="hand_1" >
    <visual>
      <geometry>
        <mesh filename="package://test_robot/stl/hand_1.STL"/>
      </geometry>
      <origin xyz="0 0 0" rpy="0 0 0" />
      <material name="white"/>
    </visual>
    <collision>
      <geometry>
        <mesh filename="package://test_robot/stl/hand_1.STL"/>
      </geometry>
      <origin xyz="0 0 0" rpy="0 0 0" />
    </collision>
    <inertial>
      <origin xyz="0 0 1" rpy="0 0 0"/>
      <mass value="1"/>
      <inertia
        ixx="1.0" ixy="0.0" ixz="0.0"
        iyy="1.0" iyz="0.0"
        izz="1.0"/>
    </inertial>
  </link>
  <link name="hand_4" >
    <visual>
      <geometry>
        <mesh filename="package://test_robot/stl/hand_4.STL"/>
      </geometry>
      <origin xyz="0 0 0" rpy="0 0 0" />
      <material name="white"/>
    </visual>
    <collision>
      <geometry>
        <mesh filename="package://test_robot/stl/hand_4.STL"/>
      </geometry>
      <origin xyz="0 0 0" rpy="0 0 0" />
    </collision>
    <inertial>
      <origin xyz="0 0 1" rpy="0 0 0"/>
      <mass value="1"/>
      <inertia
        ixx="1.0" ixy="0.0" ixz="0.0"
        iyy="1.0" iyz="0.0"
        izz="1.0"/>
    </inertial>
  </link>
  <link name="armarker" >
    <visual>
      <geometry>
        <mesh filename="package://test_robot/stl/armarker.dae"/>
      </geometry>
      <origin xyz="0 0 0" rpy="0 0 ${-0.5 * pi}" />
      <material name="white"/>
    </visual>
    <collision>
      <geometry>
        <mesh filename="package://test_robot/stl/armarker.stl"/>
      </geometry>
      <origin xyz="0 0 0" rpy="0 0 ${-0.5 * pi}" />
    </collision>
    <inertial>
      <origin xyz="0 0 1" rpy="0 0 0"/>
      <mass value="1"/>
      <inertia
        ixx="1.0" ixy="0.0" ixz="0.0"
        iyy="1.0" iyz="0.0"
        izz="1.0"/>
    </inertial>
  </link>

  <joint name="joint1" type="revolute">
    <limit effort="1000.0" lower="${-0.4 * pi}" upper="${0.4 * pi}" velocity="0.5"/>
    <origin xyz="0.082 0 0" rpy="0 0 0" />
    <axis xyz="1 0 0" />
    <parent link="base_link"/>
    <child link="link2"/>
    <dynamics damping="0.7"/>
  </joint>

  <joint name="joint2" type="revolute">
    <limit effort="1000.0" lower="${-0.6 * pi}" upper="0.09" velocity="0.5"/>
    <origin xyz="0.037 0 0" rpy="0 1.5708 0" />
    <axis xyz="0 1 0" />
    <parent link="link2"/>
    <child link="link3"/>
    <dynamics damping="0.7"/>
  </joint>

  <joint name="joint3" type="revolute">
    <limit effort="1000.0" lower="${-0.4 * pi}" upper="${0.4 * pi}" velocity="0.5"/>
    <origin xyz="0.1921 0 0" rpy="0 0 0" />
    <axis xyz="1 0 0" />
    <parent link="link3"/>
    <child link="link4"/>
    <dynamics damping="0.7"/>
  </joint>
  <joint name="joint4" type="revolute">
    <limit effort="1000.0" lower="${-0.63}" upper="${0.4 * pi}" velocity="0.5"/>
    <origin xyz="0.037 0 0" rpy="0 -1.5708 0" />
    <axis xyz="0 1 0" />
    <parent link="link4"/>
    <child link="link5"/>
    <dynamics damping="0.7"/>
  </joint>

  <joint name="joint5" type="revolute">
    <limit effort="1000.0" lower="${-0.4 * pi}" upper="${0.4 * pi}" velocity="0.5"/>
    <origin xyz="0.211 0 0.005" rpy="-1.5708 0 0" />
    <axis xyz="1 0 0" />
    <parent link="link5"/>
    <child link="link6"/>
    <dynamics damping="0.7"/>
  </joint>

  <joint name="joint6" type="revolute">
    <limit effort="1000.0" lower="-0.6" upper="0.6" velocity="0.5"/>
    <origin xyz="0.0845 0 0" rpy="0 0 0" />
    <axis xyz="0 1 0" />
    <parent link="link6"/>
    <child link="link7"/>
    <dynamics damping="0.7"/>
  </joint>
  <joint name="joint7" type="revolute">
    <limit effort="1000.0" lower="-0.25" upper="0.25" velocity="0.5"/>
    <origin xyz="0.0 0 0" rpy="0 0 0" />
    <axis xyz="0 0 1" />
    <parent link="link7"/>
    <child link="link8"/>
    <dynamics damping="0.7"/>
  </joint>
  <joint name="hand_joint_1" type="revolute">
    <limit effort="1000.0" lower="-0.9" upper="0" velocity="0.5"/>
    <origin xyz="0.0775 -0.0265 0.01475" rpy="0 0 0" />
    <axis xyz="0 1 0" />
    <parent link="link8"/>
    <child link="hand_1"/>
    <dynamics damping="0.7"/>
  </joint>
  <joint name="hand_joint_4" type="revolute">
    <limit effort="1000.0" lower="0" upper="0.9" velocity="0.5"/>
    <origin xyz="0.0795 -0.0185 -0.005" rpy="0 0 0" />
    <axis xyz="0 1 0" />
    <parent link="link8"/>
    <child link="hand_4"/>
    <dynamics damping="0.7"/>
  </joint>
  <!--joint name="camera_joint" type="fixed">
    <axis xyz="0 1 0" />
    <origin xyz="${camera_link} 0 -0.05" rpy="${0.5 * pi} 0 0"/>
    <parent link="link8"/>
    <child link="camera_link"/>
  </joint-->
  <joint name="rgbd_joint" type="fixed">
    <axis xyz="1 0 0" />
    <origin xyz="0 0.25 0.2" rpy="0 ${0.3 * pi} 0"/>
    <parent link="base_link"/>
    <child link="rgbd_link"/>
  </joint>
  <joint name="armarker_joint" type="fixed">
    <axis xyz="1 0 0" />
    <origin xyz="0.05 -0.04 0" rpy="${0.35 * pi} ${0.0 * pi} ${-0.2 * pi}" />
    <parent link="link8"/>
    <child link="armarker"/>
  </joint>
<!-- rgbd Camera -->
<!--
  <link name="camera_depth_optical_frame">
    <collision>
      <origin xyz="0 0 0" rpy="0 0 0"/>
      <geometry>
    <box size="0.001 0.001 0.001"/>
      </geometry>
    </collision>

    <visual>
      <origin xyz="0 0 0" rpy="0 0 0"/>
      <geometry>
    <box size="0.001 0.001 0.001"/>
      </geometry>
      <material name="red"/>
    </visual>

    <inertial>
      <mass value="1e-5" />
      <origin xyz="0 0 0" rpy="0 0 0"/>
      <inertia ixx="1e-6" ixy="0" ixz="0" iyy="1e-6" iyz="0" izz="1e-6" />
    </inertial>
  </link>
  <joint name="camera_depth_optical_frame_joint" type="fixed">
    <axis xyz="1 0 0" />
    <origin xyz="0 0.25 0.2" rpy="${0.2 * pi} ${-1 * pi} ${0.5 * pi}"/>
    <parent link="base_link"/>
    <child link="camera_depth_optical_frame"/>
  </joint>
-->
  <!-- rgbd Camera -->
  <!--link name="camera_link">
    <collision>
      <origin xyz="0 0 0" rpy="0 0 0"/>
      <geometry>
    <box size="${camera_link} ${camera_link} ${camera_link}"/>
      </geometry>
    </collision>

    <visual>
      <origin xyz="0 0 0" rpy="0 0 0"/>
      <geometry>
    <box size="${camera_link} ${camera_link} ${camera_link}"/>
      </geometry>
      <material name="red"/>
    </visual>

    <inertial>
      <mass value="1e-5" />
      <origin xyz="0 0 0" rpy="0 0 0"/>
      <inertia ixx="1e-6" ixy="0" ixz="0" iyy="1e-6" iyz="0" izz="1e-6" />
    </inertial>
  </link-->
  <!-- kinect -->
  <link name="rgbd_link">
    <collision>
      <origin xyz="0 0 0" rpy="0 0 0"/>
      <geometry>
    <box size="${camera_link} ${camera_link} ${camera_link}"/>
      </geometry>
    </collision>

    <visual>
      <origin xyz="0 0 0" rpy="0 0 0"/>
      <geometry>
           <mesh filename="package://moveit_resources/test/urdf/meshes/sensors/kinect_v0/kinect.dae" scale="0.001 0.001 0.001"/>
      </geometry>
      <material name="red"/>
    </visual>

    <inertial>
      <mass value="1e-5" />
      <origin xyz="0 0 0" rpy="0 0 0"/>
      <inertia ixx="1e-6" ixy="0" ixz="0" iyy="1e-6" iyz="0" izz="1e-6" />
    </inertial>
  </link>
  <transmission name="tran1">
    <type>transmission_interface/SimpleTransmission</type>
    <joint name="joint1">
      <hardwareInterface>PositionJointInterface</hardwareInterface>
    </joint>
    <actuator name="motor1">
      <hardwareInterface>PositionJointInterface</hardwareInterface>
      <mechanicalReduction>1</mechanicalReduction>
    </actuator>
  </transmission>

  <transmission name="tran2">
    <type>transmission_interface/SimpleTransmission</type>
    <joint name="joint2">
      <hardwareInterface>PositionJointInterface</hardwareInterface>
    </joint>
    <actuator name="motor2">
      <hardwareInterface>PositionJointInterface</hardwareInterface>
      <mechanicalReduction>1</mechanicalReduction>
    </actuator>
  </transmission>
  <transmission name="tran3">
    <type>transmission_interface/SimpleTransmission</type>
    <joint name="joint3">
      <hardwareInterface>PositionJointInterface</hardwareInterface>
    </joint>
    <actuator name="motor3">
      <hardwareInterface>PositionJointInterface</hardwareInterface>
      <mechanicalReduction>1</mechanicalReduction>
    </actuator>
  </transmission>

  <transmission name="tran4">
    <type>transmission_interface/SimpleTransmission</type>
    <joint name="joint4">
      <hardwareInterface>PositionJointInterface</hardwareInterface>
    </joint>
    <actuator name="motor4">
      <hardwareInterface>PositionJointInterface</hardwareInterface>
      <mechanicalReduction>1</mechanicalReduction>
    </actuator>
  </transmission>
  <transmission name="tran5">
    <type>transmission_interface/SimpleTransmission</type>
    <joint name="joint5">
      <hardwareInterface>PositionJointInterface</hardwareInterface>
    </joint>
    <actuator name="motor5">
      <hardwareInterface>PositionJointInterface</hardwareInterface>
      <mechanicalReduction>1</mechanicalReduction>
    </actuator>
  </transmission>

  <transmission name="tran6">
    <type>transmission_interface/SimpleTransmission</type>
    <joint name="joint6">
      <hardwareInterface>PositionJointInterface</hardwareInterface>
    </joint>
    <actuator name="motor6">
      <hardwareInterface>PositionJointInterface</hardwareInterface>
      <mechanicalReduction>1</mechanicalReduction>
    </actuator>
  </transmission>
  <transmission name="tran7">
    <type>transmission_interface/SimpleTransmission</type>
    <joint name="joint7">
      <hardwareInterface>PositionJointInterface</hardwareInterface>
    </joint>
    <actuator name="motor7">
      <hardwareInterface>PositionJointInterface</hardwareInterface>
      <mechanicalReduction>1</mechanicalReduction>
    </actuator>
  </transmission>
  <transmission name="tran8">
    <type>transmission_interface/SimpleTransmission</type>
    <joint name="hand_joint_1">
      <hardwareInterface>PositionJointInterface</hardwareInterface>
    </joint>
    <actuator name="motor8">
      <hardwareInterface>PositionJointInterface</hardwareInterface>
      <mechanicalReduction>1</mechanicalReduction>
    </actuator>
  </transmission>
  <transmission name="tran9">
    <type>transmission_interface/SimpleTransmission</type>
    <joint name="hand_joint_4">
      <hardwareInterface>PositionJointInterface</hardwareInterface>
    </joint>
    <actuator name="motor8">
      <hardwareInterface>PositionJointInterface</hardwareInterface>
      <mechanicalReduction>1</mechanicalReduction>
    </actuator>
  </transmission>
</robot>
