<?xml version="1.0" ?>
<!-- =================================================================================== -->
<!-- |    This document was autogenerated by xacro from /home/bmi/Documents/ws_moveit/src/bmirobot_pkg/bmirobot_description/urdf/bmirobot_V4.xacro | -->
<!-- |    EDITING THIS FILE BY HAND IS NOT RECOMMENDED                                 | -->
<!-- =================================================================================== -->
<robot name="bmirobot" xmlns:xacro="http://www.ros.org/wiki/xacro">
  <!-- Space btw top of beam and the each joint -->
  <material name="black">
    <color rgba="0.0 0.0 0.0 1.0"/>
  </material>
  <material name="blue">
    <color rgba="0.0 0.0 0.8 1.0"/>
  </material>
  <material name="green">
    <color rgba="0.0 0.8 0.0 1.0"/>
  </material>
  <material name="grey">
    <color rgba="0.2 0.2 0.2 1.0"/>
  </material>
  <material name="orange">
    <color rgba="1.0 0.423529411765 0.0392156862745 1.0"/>
  </material>
  <material name="brown">
    <color rgba="0.870588235294 0.811764705882 0.764705882353 1.0"/>
  </material>
  <material name="red">
    <color rgba="0.8 0.0 0.0 1.0"/>
  </material>
  <material name="white">
    <color rgba="1.0 1.0 1.0 1.0"/>
  </material>
  <!-- Used for fixing robot to Gazebo 'base_link' -->
  <link name="world"/>
  <joint name="fixed" type="fixed">
    <parent link="world"/>
    <child link="odom_combined"/>
  </joint>
  <link name="odom_combined"/>
  <joint name="virtual_joint" type="fixed">
    <parent link="odom_combined"/>
    <child link="base_link"/>
    <origin rpy="0 0 0" xyz="0 0 0.45"/>
  </joint>
  <link name="base_link">
    <visual>
      <geometry>
        <mesh filename="package://test_robot/stl/link1.STL"/>
      </geometry>
      <material name="blue"/>
    </visual>
    <collision>
      <geometry>
        <mesh filename="package://test_robot/stl/link1.STL"/>
      </geometry>
    </collision>
    <inertial>
      <origin rpy="0 0 0" xyz="0 0 1"/>
      <mass value="1"/>
      <inertia ixx="1.0" ixy="0.0" ixz="0.0" iyy="1.0" iyz="0.0" izz="1.0"/>
    </inertial>
  </link>
  <link name="link2">
    <visual>
      <geometry>
        <mesh filename="package://test_robot/stl/link2.STL"/>
      </geometry>
      <origin rpy="0 0 0" xyz="0 0 0"/>
      <material name="white"/>
    </visual>
    <collision>
      <geometry>
        <mesh filename="package://test_robot/stl/link2.STL"/>
      </geometry>
      <origin rpy="0 0 0" xyz="0 0 0"/>
    </collision>
    <inertial>
      <origin rpy="0 0 0" xyz="0 0 1"/>
      <mass value="1"/>
      <inertia ixx="1.0" ixy="0.0" ixz="0.0" iyy="1.0" iyz="0.0" izz="1.0"/>
    </inertial>
  </link>
  <link name="link3">
    <visual>
      <geometry>
        <mesh filename="package://test_robot/stl/link3.STL"/>
      </geometry>
      <origin rpy="0 0 0" xyz="0 0 0"/>
      <material name="blue"/>
    </visual>
    <collision>
      <geometry>
        <mesh filename="package://test_robot/stl/link3.STL"/>
      </geometry>
      <origin rpy="0 0 0" xyz="0 0 0"/>
    </collision>
    <inertial>
      <origin rpy="0 0 0" xyz="0 0 1"/>
      <mass value="1"/>
      <inertia ixx="1.0" ixy="0.0" ixz="0.0" iyy="1.0" iyz="0.0" izz="1.0"/>
    </inertial>
  </link>
  <link name="link4">
    <visual>
      <geometry>
        <mesh filename="package://test_robot/stl/link2.STL"/>
      </geometry>
      <origin rpy="0 0 0" xyz="0 0 0"/>
      <material name="white"/>
    </visual>
    <collision>
      <geometry>
        <mesh filename="package://test_robot/stl/link2.STL"/>
      </geometry>
      <origin rpy="0 0 0" xyz="0 0 0"/>
    </collision>
    <inertial>
      <origin rpy="0 0 0" xyz="0 0 1"/>
      <mass value="1"/>
      <inertia ixx="1.0" ixy="0.0" ixz="0.0" iyy="1.0" iyz="0.0" izz="1.0"/>
    </inertial>
  </link>
  <link name="link5">
    <visual>
      <geometry>
        <mesh filename="package://test_robot/stl/link5.STL"/>
      </geometry>
      <origin rpy="0 0 0" xyz="0 0 0"/>
      <material name="blue"/>
    </visual>
    <collision>
      <geometry>
        <mesh filename="package://test_robot/stl/link5.STL"/>
      </geometry>
      <origin rpy="0 0 0" xyz="0 0 0"/>
    </collision>
    <inertial>
      <origin rpy="0 0 0" xyz="0 0 1"/>
      <mass value="1"/>
      <inertia ixx="1.0" ixy="0.0" ixz="0.0" iyy="1.0" iyz="0.0" izz="1.0"/>
    </inertial>
  </link>
  <link name="link6">
    <visual>
      <geometry>
        <mesh filename="package://test_robot/stl/link6.STL"/>
      </geometry>
      <origin rpy="0 0 0" xyz="0 0 0"/>
      <material name="red"/>
    </visual>
    <collision>
      <geometry>
        <mesh filename="package://test_robot/stl/link6.STL"/>
      </geometry>
      <origin rpy="0 0 0" xyz="0 0 0"/>
    </collision>
    <inertial>
      <origin rpy="0 0 0" xyz="0 0 1"/>
      <mass value="1"/>
      <inertia ixx="1.0" ixy="0.0" ixz="0.0" iyy="1.0" iyz="0.0" izz="1.0"/>
    </inertial>
  </link>
  <link name="link7">
    <visual>
      <geometry>
        <mesh filename="package://test_robot/stl/link7.STL"/>
      </geometry>
      <origin rpy="0 0 0" xyz="0 0 0"/>
      <material name="blue"/>
    </visual>
    <collision>
      <geometry>
        <mesh filename="package://test_robot/stl/link7.STL"/>
      </geometry>
      <origin rpy="0 0 0" xyz="0 0 0"/>
    </collision>
    <inertial>
      <origin rpy="0 0 0" xyz="0 0 1"/>
      <mass value="1"/>
      <inertia ixx="1.0" ixy="0.0" ixz="0.0" iyy="1.0" iyz="0.0" izz="1.0"/>
    </inertial>
  </link>
  <link name="link8">
    <visual>
      <geometry>
        <mesh filename="package://test_robot/stl/link8.STL"/>
      </geometry>
      <origin rpy="0 0 0" xyz="0 0 0"/>
      <material name="red"/>
    </visual>
    <collision>
      <geometry>
        <mesh filename="package://test_robot/stl/link8.STL"/>
      </geometry>
      <origin rpy="0 0 0" xyz="0 0 0"/>
    </collision>
    <inertial>
      <origin rpy="0 0 0" xyz="0 0 1"/>
      <mass value="1"/>
      <inertia ixx="1.0" ixy="0.0" ixz="0.0" iyy="1.0" iyz="0.0" izz="1.0"/>
    </inertial>
  </link>
  <link name="hand_1">
    <visual>
      <geometry>
        <mesh filename="package://test_robot/stl/hand_1.STL"/>
      </geometry>
      <origin rpy="0 0 0" xyz="0 0 0"/>
      <material name="white"/>
    </visual>
    <collision>
      <geometry>
        <mesh filename="package://test_robot/stl/hand_1.STL"/>
      </geometry>
      <origin rpy="0 0 0" xyz="0 0 0"/>
    </collision>
    <inertial>
      <origin rpy="0 0 0" xyz="0 0 1"/>
      <mass value="1"/>
      <inertia ixx="1.0" ixy="0.0" ixz="0.0" iyy="1.0" iyz="0.0" izz="1.0"/>
    </inertial>
  </link>
  <link name="hand_4">
    <visual>
      <geometry>
        <mesh filename="package://test_robot/stl/hand_4.STL"/>
      </geometry>
      <origin rpy="0 0 0" xyz="0 0 0"/>
      <material name="white"/>
    </visual>
    <collision>
      <geometry>
        <mesh filename="package://test_robot/stl/hand_4.STL"/>
      </geometry>
      <origin rpy="0 0 0" xyz="0 0 0"/>
    </collision>
    <inertial>
      <origin rpy="0 0 0" xyz="0 0 1"/>
      <mass value="1"/>
      <inertia ixx="1.0" ixy="0.0" ixz="0.0" iyy="1.0" iyz="0.0" izz="1.0"/>
    </inertial>
  </link>
  <joint name="joint1" type="revolute">
    <limit effort="1000.0" lower="-1.25663706144" upper="1.25663706144" velocity="0.5"/>
    <origin rpy="0 0 0" xyz="0.026 0 0"/>
    <axis xyz="1 0 0"/>
    <parent link="base_link"/>
    <child link="link2"/>
    <dynamics damping="0.7"/>
  </joint>
  <joint name="joint2" type="revolute">
    <limit effort="1000.0" lower="-1.88495559215" upper="0.575958653158" velocity="0.5"/>
    <origin rpy="0 1.5708 0" xyz="0.063 0 0"/>
    <axis xyz="0 1 0"/>
    <parent link="link2"/>
    <child link="link3"/>
    <dynamics damping="0.7"/>
  </joint>
  <joint name="joint3" type="revolute">
    <limit effort="1000.0" lower="-1.25663706144" upper="1.25663706144" velocity="0.5"/>
    <origin rpy="0 0 0" xyz="0.1826 0 0"/>
    <axis xyz="1 0 0"/>
    <parent link="link3"/>
    <child link="link4"/>
    <dynamics damping="0.7"/>
  </joint>
  <joint name="joint4" type="revolute">
    <limit effort="1000.0" lower="-0.63" upper="1.25663706144" velocity="0.5"/>
    <origin rpy="0 -1.5708 0" xyz="0.063 0 0"/>
    <axis xyz="0 1 0"/>
    <parent link="link4"/>
    <child link="link5"/>
    <dynamics damping="0.7"/>
  </joint>
  <joint name="joint5" type="revolute">
    <limit effort="1000.0" lower="-2.51327412287" upper="2.51327412287" velocity="0.5"/>
    <origin rpy="-1.5708 0 0" xyz="0.211 0 0.000"/>
    <axis xyz="1 0 0"/>
    <parent link="link5"/>
    <child link="link6"/>
    <dynamics damping="0.7"/>
  </joint>
  <joint name="joint6" type="revolute">
    <limit effort="1000.0" lower="-2.51327412287" upper="-2.51327412287" velocity="0.5"/>
    <origin rpy="0 0.0 0" xyz="0.1845 0 0"/>
    <axis xyz="0 1 0"/>
    <parent link="link6"/>
    <child link="link7"/>
    <dynamics damping="0.7"/>
  </joint>
  <joint name="joint7" type="revolute">
    <limit effort="1000.0" lower="-0.25" upper="0.25" velocity="0.5"/>
    <origin rpy="0 0.0 0" xyz="0.1 0 0"/>
    <axis xyz="0 0 1"/>
    <parent link="link7"/>
    <child link="link8"/>
    <dynamics damping="0.7"/>
  </joint>
  <joint name="hand_joint_1" type="revolute">
    <limit effort="1000.0" lower="-0.9" upper="0" velocity="0.5"/>
    <origin rpy="0 0 0" xyz="0.0775 -0.0265 0.01475"/>
    <axis xyz="0 1 0"/>
    <parent link="link8"/>
    <child link="hand_1"/>
    <dynamics damping="0.7"/>
  </joint>
  <joint name="hand_joint_4" type="revolute">
    <limit effort="1000.0" lower="0" upper="0.9" velocity="0.5"/>
    <origin rpy="0 0 0" xyz="0.0795 -0.0185 -0.005"/>
    <axis xyz="0 1 0"/>
    <parent link="link8"/>
    <child link="hand_4"/>
    <dynamics damping="0.7"/>
  </joint>
  <!--joint name="camera_joint" type="fixed">
    <axis xyz="0 1 0" />
    <origin xyz="${camera_link} 0 -0.05" rpy="${0.5 * pi} 0 0"/>
    <parent link="link8"/>
    <child link="camera_link"/>
  </joint-->
  <joint name="rgbd_joint" type="fixed">
    <axis xyz="1 0 0"/>
    <origin rpy="0 0.942477796077 0" xyz="0 0.25 0.2"/>
    <parent link="base_link"/>
    <child link="rgbd_link"/>
  </joint>
  <!-- rgbd Camera -->
  <!--
  <link name="camera_depth_optical_frame">
    <collision>
      <origin xyz="0 0 0" rpy="0 0 0"/>
      <geometry>
    <box size="0.001 0.001 0.001"/>
      </geometry>
    </collision>

    <visual>
      <origin xyz="0 0 0" rpy="0 0 0"/>
      <geometry>
    <box size="0.001 0.001 0.001"/>
      </geometry>
      <material name="red"/>
    </visual>

    <inertial>
      <mass value="1e-5" />
      <origin xyz="0 0 0" rpy="0 0 0"/>
      <inertia ixx="1e-6" ixy="0" ixz="0" iyy="1e-6" iyz="0" izz="1e-6" />
    </inertial>
  </link>
  <joint name="camera_depth_optical_frame_joint" type="fixed">
    <axis xyz="1 0 0" />
    <origin xyz="0 0.25 0.2" rpy="${0.2 * pi} ${-1 * pi} ${0.5 * pi}"/>
    <parent link="base_link"/>
    <child link="camera_depth_optical_frame"/>
  </joint>
-->
  <!-- rgbd Camera -->
  <!--link name="camera_link">
    <collision>
      <origin xyz="0 0 0" rpy="0 0 0"/>
      <geometry>
    <box size="${camera_link} ${camera_link} ${camera_link}"/>
      </geometry>
    </collision>

    <visual>
      <origin xyz="0 0 0" rpy="0 0 0"/>
      <geometry>
    <box size="${camera_link} ${camera_link} ${camera_link}"/>
      </geometry>
      <material name="red"/>
    </visual>

    <inertial>
      <mass value="1e-5" />
      <origin xyz="0 0 0" rpy="0 0 0"/>
      <inertia ixx="1e-6" ixy="0" ixz="0" iyy="1e-6" iyz="0" izz="1e-6" />
    </inertial>
  </link-->
  <!-- kinect -->
  <link name="rgbd_link">
    <collision>
      <origin rpy="0 0 0" xyz="0 0 0"/>
      <geometry>
        <box size="0.025 0.025 0.025"/>
      </geometry>
    </collision>
    <visual>
      <origin rpy="0 0 0" xyz="0 0 0"/>
      <geometry>
        <mesh filename="package://moveit_resources/test/urdf/meshes/sensors/kinect_v0/kinect.dae" scale="0.001 0.001 0.001"/>
      </geometry>
      <material name="red"/>
    </visual>
    <inertial>
      <mass value="1e-5"/>
      <origin rpy="0 0 0" xyz="0 0 0"/>
      <inertia ixx="1e-6" ixy="0" ixz="0" iyy="1e-6" iyz="0" izz="1e-6"/>
    </inertial>
  </link>
  <transmission name="tran1">
    <type>transmission_interface/SimpleTransmission</type>
    <joint name="joint1">
      <hardwareInterface>PositionJointInterface</hardwareInterface>
    </joint>
    <actuator name="motor1">
      <hardwareInterface>PositionJointInterface</hardwareInterface>
      <mechanicalReduction>1</mechanicalReduction>
    </actuator>
  </transmission>
  <transmission name="tran2">
    <type>transmission_interface/SimpleTransmission</type>
    <joint name="joint2">
      <hardwareInterface>PositionJointInterface</hardwareInterface>
    </joint>
    <actuator name="motor2">
      <hardwareInterface>PositionJointInterface</hardwareInterface>
      <mechanicalReduction>1</mechanicalReduction>
    </actuator>
  </transmission>
  <transmission name="tran3">
    <type>transmission_interface/SimpleTransmission</type>
    <joint name="joint3">
      <hardwareInterface>PositionJointInterface</hardwareInterface>
    </joint>
    <actuator name="motor3">
      <hardwareInterface>PositionJointInterface</hardwareInterface>
      <mechanicalReduction>1</mechanicalReduction>
    </actuator>
  </transmission>
  <transmission name="tran4">
    <type>transmission_interface/SimpleTransmission</type>
    <joint name="joint4">
      <hardwareInterface>PositionJointInterface</hardwareInterface>
    </joint>
    <actuator name="motor4">
      <hardwareInterface>PositionJointInterface</hardwareInterface>
      <mechanicalReduction>1</mechanicalReduction>
    </actuator>
  </transmission>
  <transmission name="tran5">
    <type>transmission_interface/SimpleTransmission</type>
    <joint name="joint5">
      <hardwareInterface>PositionJointInterface</hardwareInterface>
    </joint>
    <actuator name="motor5">
      <hardwareInterface>PositionJointInterface</hardwareInterface>
      <mechanicalReduction>1</mechanicalReduction>
    </actuator>
  </transmission>
  <transmission name="tran6">
    <type>transmission_interface/SimpleTransmission</type>
    <joint name="joint6">
      <hardwareInterface>PositionJointInterface</hardwareInterface>
    </joint>
    <actuator name="motor6">
      <hardwareInterface>PositionJointInterface</hardwareInterface>
      <mechanicalReduction>1</mechanicalReduction>
    </actuator>
  </transmission>
  <transmission name="tran7">
    <type>transmission_interface/SimpleTransmission</type>
    <joint name="joint7">
      <hardwareInterface>PositionJointInterface</hardwareInterface>
    </joint>
    <actuator name="motor7">
      <hardwareInterface>PositionJointInterface</hardwareInterface>
      <mechanicalReduction>1</mechanicalReduction>
    </actuator>
  </transmission>
  <transmission name="tran8">
    <type>transmission_interface/SimpleTransmission</type>
    <joint name="hand_joint_1">
      <hardwareInterface>PositionJointInterface</hardwareInterface>
    </joint>
    <actuator name="motor8">
      <hardwareInterface>PositionJointInterface</hardwareInterface>
      <mechanicalReduction>1</mechanicalReduction>
    </actuator>
  </transmission>
  <transmission name="tran9">
    <type>transmission_interface/SimpleTransmission</type>
    <joint name="hand_joint_4">
      <hardwareInterface>PositionJointInterface</hardwareInterface>
    </joint>
    <actuator name="motor8">
      <hardwareInterface>PositionJointInterface</hardwareInterface>
      <mechanicalReduction>1</mechanicalReduction>
    </actuator>
  </transmission>
</robot>

